Workbook

Sheet Read Me
A1: Pakistan AI Policy Monitor
A2: Evidence Register and Coverage Log | 18 August–3 September 2026 (UTC)
A3: Search cutoff: 2026-09-03 04:15 UTC | Evidence and lifecycle status should be rechecked before any later reuse.
A5: Interpretation boundary
A6: Comprehensive with respect to the supplied files and documented verification searches; not proof that every relevant public event was captured.
A8: Temporal caveat — The supplied corpus contains 14 briefing units against a nominal 1,440 runs for exactly 15 days at a 15-minute cadence. Negative findings are therefore bounded to the supplied files and documented searches; missing intervals are never imputed.
A11: Formula-driven control totals | G11: Coverage controls
A12: Control | B12: Live value | C12: Unit | D12: Expected | E12: Reconciliation | G12: Metric | H12: Live value | I12: Interpretation
A13: Evidence register rows | B13: =COUNTA('Evidence Register'!$A$5:$A$56) -> 52 | C13: records | D13: 52 | E13: =IF(B13=D13,"PASS","CHECK") -> PASS | G13: Nominal expected runs | H13: ='Coverage & Gaps'!$B$6 -> 1440 | I13: Exactly 15 days × 24 hours × 4 runs/hour
A14: In-period / verification-discovered | B14: =COUNTIF('Evidence Register'!$A$5:$A$56,"EVT-*") -> 36 | C14: records | D14: 36 | E14: =IF(B14=D14,"PASS","CHECK") -> PASS | G14: Observed briefing units | H14: ='Coverage & Gaps'!$B$7 -> 14 | I14: Normalized supplied briefing units
A15: Baseline / context | B15: =COUNTIF('Evidence Register'!$A$5:$A$56,"BASE-*") -> 16 | C15: records | D15: 16 | E15: =IF(B15=D15,"PASS","CHECK") -> PASS | G15: Nominal missing runs | H15: ='Coverage & Gaps'!$B$8 -> 1426 | I15: Expected minus observed
A16: Baseline carry-in | B16: =COUNTIFS('Evidence Register'!$A$5:$A$56,"BASE-*",'Evidence Register'!$Z$5:$Z$56,"BASELINE_CARRY_IN") -> 13 | C16: records | D16: 13 | E16: =IF(B16=D16,"PASS","CHECK") -> PASS | G16: Observed share | H16: ='Coverage & Gaps'!$B$9 -> 0.0097222222 | I16: Observed divided by nominal expected
A17: Baseline contradicted / unresolved | B17: =COUNTIFS('Evidence Register'!$A$5:$A$56,"BASE-*",'Evidence Register'!$Z$5:$Z$56,"CONTRADICTED_OR_UNRESOLVED") -> 3 | C17: records | D17: 3 | E17: =IF(B17=D17,"PASS","CHECK") -> PASS | G17: Strict-window share | H17: ='Coverage & Gaps'!$B$12 -> 0.0098024254 | I17: Strict observed minutes divided by observed span
A18: Sources | B18: =COUNTA(Sources!$A$5:$A$115) -> 111 | C18: records | D18: 111 | E18: =IF(B18=D18,"PASS","CHECK") -> PASS | G18: Search cutoff | H18: 2026-09-03T04:15:00Z | I18: Current-source verification boundary
A19: Briefing units | B19: =COUNTA('Briefing Units'!$A$5:$A$18) -> 14 | C19: units | D19: 14 | E19: =IF(B19=D19,"PASS","CHECK") -> PASS
A20: Exclusions | B20: =COUNTA(Exclusions!$A$5:$A$17) -> 13 | C20: items | D20: 13 | E20: =IF(B20=D20,"PASS","CHECK") -> PASS
A21: Watch items | B21: =COUNTA(Watchlist!$A$5:$A$18) -> 14 | C21: items | D21: 14 | E21: =IF(B21=D21,"PASS","CHECK") -> PASS
A22: High confidence | B22: =COUNTIF('Evidence Register'!$V$5:$V$56,"High") -> 32 | C22: records | D22: 32 | E22: =IF(B22=D22,"PASS","CHECK") -> PASS
A23: Medium confidence | B23: =COUNTIF('Evidence Register'!$V$5:$V$56,"Medium") -> 16 | C23: records | D23: 16 | E23: =IF(B23=D23,"PASS","CHECK") -> PASS
A24: Low confidence | B24: =COUNTIF('Evidence Register'!$V$5:$V$56,"Low") -> 4 | C24: records | D24: 4 | E24: =IF(B24=D24,"PASS","CHECK") -> PASS
A27: Evidence model and source hierarchy
A28: Layer | B28: Rule | C28: Why it matters | G28: Priority | H28: Source class | I28: Use
A29: Verified facts | B29: State only what an accessible record directly supports. | C29: Prevents announcement language from becoming implementation evidence. | G29: 1 | H29: Primary law, gazette, regulator, procurement register | I29: Lifecycle and operative-text conclusions
A30: Source claims | B30: Attribute unverified operational, scale, or outcome claims. | C30: Preserves what institutions said without adopting it as fact. | G30: 2 | H30: Official ministry, authority, institution, company | I30: Event facts and attributed claims
A31: Interpretation | B31: Separate analytical synthesis from sourced fact. | C31: Makes reasoning auditable and contestable. | G31: 3 | H31: Independent reporting | I31: Corroboration, context, and contested details
A32: Forward implications | B32: Express future-facing consequences as bounded scenarios. | C32: Avoids converting plausible pathways into forecasts. | G32: 4 | H32: Briefing corpus | I32: Discovery provenance only; never independent corroboration
A33: Lifecycle | B33: Classify proposal, consultation, approval, award, signing, delivery, and operation separately. | C33: Prevents stage inflation.
A34: Conflict | B34: Retain both dated versions and identify mutable-source limits. | C34: Preserves the WHO 24-Aug capture versus 28-Aug live-page discrepancy.
A37: Workbook navigation
A38: Evidence Register | B38: 52 distinct event/baseline records with lifecycle, confidence, facts, claims, analysis, implications, and source URLs.
A39: Coverage & Gaps | B39: Cadence controls, normalized observed span, and all 13 inter-briefing gaps.
A40: Exclusions | B40: Every out-of-scope, duplicate, or unsupported item and its disposition.
A41: Briefing Units | B41: B001–B014 source provenance, normalized UTC/PKT windows, timing issues, and SHA-256 hashes.
A42: Sources | B42: S001–S111 source register with plain-text URLs and limitations.
A43: Watchlist | B43: W001–W014 future triggers and verification tasks.
A44: File Inventory | B44: All 13 received top-level files, readability, metadata, hashes, and inclusion decisions.
A45: Methodology | B45: Reproducibility chain, source hierarchy, lifecycle rules, confidence rubric, and refresh protocol.

Sheet Evidence Register
A1: Evidence Register
A2: One row per distinct event or retained baseline/context record. Facts, claims, analysis, implications, uncertainty, and lifecycle remain separate.
A4: Event ID | B4: Normalized Event Title | C4: Category | D4: Institution | E4: Geography | F4: Event Date | G4: Publication Date | H4: First Detected | I4: Last Updated | J4: Briefing File References | K4: Primary Source IDs | L4: Primary Source URLs | M4: Corroborating Source IDs | N4: Corroborating Source URLs | O4: Status | P4: Verified Facts | Q4: Source Claims | R4: What Changed | S4: Significance | T4: Analytical Interpretation | U4: Forward Implications | V4: Confidence | W4: Confidence Reason | X4: Unresolved Issues | Y4: Inclusion Decision | Z4: Lifecycle
A5: EVT-GOOG-20260818-OFFICE | B5: Google Pakistan office inauguration claim | C5: GOOGLE_CORPORATE_PRESENCE | D5: Google; Government of Pakistan | E5: Islamabad / national | F5: 46252 | G5: 2026-08-18; retrospective PDA item 2026-09-01 | H5: 2026-08-18T19:38Z (B001) | I5: 2026-09-03T02:21Z (B014) | J5: B001; B002; B003; B004; B005; B006; B007; B008; B009; B010; B011; B012; B013; B014 | K5: S074; S075; S081; S082; S083 | L5: https://pid.gov.pk/site/press_detail/33638 | https://pda.gov.pk/press-details.php?id=google-opens-office-in-pakistan | https://about.google/company-info/locations/ | https://cloud.google.com/about/locations | https://datacenters.google/locations/ | M5: S076; S084 | N5: https://www.dawn.com/news/2023681 | https://www.google.com/about/careers/applications/jobs/results?location=Pakistan | O5: government/company-reported inauguration; physical operation unverified | P5: A plaque-marking ceremony involving the prime minister and a Google delegation occurred at Prime Minister House on 18 August. Google’s current canonical office, Cloud-region and owned-data-centre directories showed no Pakistan listing at the verification cutoff. | Q5: Pakistani authorities and contemporaneous reporting called the event the opening or establishment of Google’s first local office. | R5: The reporting period added a high-level ceremony and public local-office claim, but later checks did not supply premises-level evidence. | S5: The distinction affects how investors, regulators and users should understand local accountability, staffing, tax presence, and data-hosting implications. | T5: Evidence supports an announced/local corporate presence, not a confidently verified staffed operational office at a disclosed physical location. | U5: Verify street address, premises operator, occupancy, employing entity, staff, mandate and any local processing/hosting before upgrading status. | V5: Medium | W5: High confidence in the ceremony and directory state; insufficient evidence for physical operation, location and timing of an operating office. | X5: Physical address; office type; occupancy; headcount; employing entity; mandate; investment; data processing; hosting jurisdiction. | Y5: include with explicit qualification | Z5: IN_SPAN_DEVELOPMENT
A6: EVT-GOOG-20260821-MOU | B6: Government of Pakistan–Google framework MoU and programme announcements | C6: FUNDING_INVESTMENT_PARTNERSHIP | D6: Google; MoITT; Government of Pakistan | E6: Islamabad / national | F6: 46255 | G6: 2026-08-21 and 2026-08-24 | H6: 2026-08-21T15:05Z (B003) | I6: 2026-09-03T02:21Z (B014) | J6: B003; B005; B006; B010; B014 | K6: S077 | L6: https://pid.gov.pk/site/press_detail/33684 | M6: S078; S079 | N6: https://www.moib.gov.pk/News/66341 | https://pid.gov.pk/site/press_detail/33645 | O6: signed/announced framework MoU; delivery not evidenced | P6: PID records a framework MoU dated 21 August and programme targets including 150,000 Career Certificates in 2026 and exploration of one-year student access to Google AI Plus/Gemini and NotebookLM, an Islamabad AI centre, and FBR support. | Q6: Government releases report earlier programme outputs and prospective skills, education, SME, agriculture, payments, app and gaming initiatives. | R6: A cooperation framework and numeric training target entered the record; no budget release, beneficiary completion, centre opening or system acceptance was found. | S6: The package could shape workforce supply and public-sector vendor relationships, but implementation terms determine actual value and data-governance exposure. | T6: This is a programme-intent milestone, not realized investment or delivered capacity. | U6: Seek the signed instrument, workplan, budgets, selection rules, data flows, hosting terms and output audits. | V6: Medium | W6: Strong official evidence of the announcement; primary instrument and delivery evidence unavailable. | X6: Signed text; budget; beneficiary selection; centre site/operator/timeline; data flows; local hosting; independent outcome audit. | Y6: include | Z6: IN_SPAN_DEVELOPMENT
A7: EVT-REG-20260821-PVARA | B7: PVARA virtual-asset service regulations notified | C7: DATA_PROTECTION_GOVERNANCE | D7: Pakistan Virtual Assets Regulatory Authority | E7: Federal / Pakistan | F7: 46255 | G7: 46255 | H7: 2026-08-22T15:05Z (B004) | I7: 2026-08-31T14:55Z (B012) | J7: B004; B005; B006; B007; B008; B011; B012 | K7: S018; S019; S020 | L7: https://pvara.gov.pk/documents/Pakistan%20Virtual%20Asset%20Services%20Regulations,%202026%20-%20Notified%2021%20August%202026.pdf | https://pvara.gov.pk/documents/Pakistan%20Virtual%20Asset%20Services%20Activity%20Specific%20Regulations,%202026%20-%20Notified%2021%20August%202026.pdf | https://pvara.gov.pk/licensing | M7: S017; S021 | N7: https://pvara.gov.pk/regulations | https://radio.gov.pk/22-08-2026/pakistan-introduces-transparent-regulatory-system-for-digital-economy | O7: notified and effective regulations | P7: S.R.O. 1419(I)/2026 and S.R.O. 1420(I)/2026 were notified on 21 August and SRO 1419 states commencement on Gazette notification unless a later date is specified. Verified duties include technology/cyber controls, cloud and cross-border safeguards, incident reporting and personal-data programmes. General and activity-specific records are retained at least seven years; material cyber/BCDR notice is due within 24 hours, an interim update within five working days, final report within 30 calendar days, and personal-data incident notice within 72 hours. | Q7: The summary page states a minimum ten-year record-keeping rule, but the operative regulations use seven years generally; ten years applies in a narrower unclaimed-wallet/assets context. | R7: The framework moved from enabling legislation/guidance to two operative sector regulations. | S7: VASPs now face concrete licensing, governance, cloud, cyber, algorithm and personal-data obligations with reportable deadlines. | T7: This was the clearest binding digital-regulatory development in the supplied monitoring span. | U7: Track transitional applications, licensing decisions, supervisory guidance, enforcement and cloud/cross-border implementation. | V7: High | W7: Operative Gazette texts were opened and checked directly. | X7: First licences/NOCs; enforcement; treatment of specific cloud architectures; publication of reasoned decisions. | Y7: include | Z7: IN_SPAN_DEVELOPMENT
A8: EVT-CYB-20260824-PKCERT16 | B8: PKCERT publishes Advisory 16 on synchronized passkeys | C8: CYBERSECURITY | D8: PKCERT | E8: Federal / Pakistan | F8: 2026-08-24 (identifier and PDF metadata) | G8: 2026-08-24 (metadata-supported) | H8: 2026-08-24T19:25Z (B006) | I8: 2026-09-03T02:21Z (B014) | J8: B006; B007; B008; B009; B010; B011; B012; B013; B014 | K8: S022; S023 | L8: https://pkcert.gov.pk/advisories.asp | https://pkcert.gov.pk/advisory/26/16.pdf | O8: published advisory | P8: The live register lists Advisory 16, NCA-16.240826, concerning malware targeting synchronized passkeys on compromised Windows systems. | R8: It superseded the corpus’s prior observation that Advisory 15 topped the register. | S8: It is an operational cyber-risk publication, not a new law or incident disclosure. | T8: Useful threat guidance, but no evidence of a Pakistan-specific breach or mandated remediation was located. | U8: Track agency adoption and any incident reporting. | V8: High | W8: Official PDF and register; date is metadata-supported but exact release time is unavailable. | X8: Exact publication timestamp; implementation by covered entities. | Y8: include | Z8: IN_SPAN_DEVELOPMENT
A9: EVT-CYB-20260824-PKCERT17 | B9: PKCERT publishes Advisory 17 on an Acrobat extension exposure | C9: CYBERSECURITY | D9: PKCERT | E9: Federal / Pakistan | F9: 2026-08-24 (identifier and PDF metadata) | G9: 2026-08-24 (metadata-supported) | H9: 2026-08-24T19:25Z (B006) | I9: 2026-09-03T02:21Z (B014) | J9: B006; B007; B008; B009; B010; B011; B012; B013; B014 | K9: S022; S024 | L9: https://pkcert.gov.pk/advisories.asp | https://pkcert.gov.pk/advisory/26/17.pdf | O9: published advisory | P9: The live register lists Advisory 17, NCA-17.240826, on an Adobe Acrobat Chrome extension vulnerability exposing WhatsApp Web sessions. | R9: The advisory became the top visible 2026 listing by the B006 cutoff. | S9: The notice expands official threat guidance relevant to organizational browsers and messaging sessions. | T9: It should not be treated as evidence of a Pakistan-specific compromise. | U9: Monitor follow-on directives or incident notices. | V9: High | W9: Official PDF and register; exact release time is unavailable. | X9: Exact publication timestamp; affected-estate evidence; implementation uptake. | Y9: include | Z9: IN_SPAN_DEVELOPMENT
A10: EVT-TEL-20260828-AMENDMENT-WITHDRAWN | B10: Pakistan Telecommunication amendment bill withdrawn | C10: PLATFORM_TELECOM | D10: Parliament; MoITT | E10: Federal / Islamabad | F10: 46262 | G10: 46262 | H10: 2026-08-28T14:52Z (B009) | I10: 2026-08-29T14:38Z (B010) | J10: B009; B010 | K10: S025; S026 | L10: https://pid.gov.pk/site/press_detail/33741 | https://www.senate.gov.pk/en/gbna.php?catid=186&cattitle=Bills&leftcatid=279&subcatid=276 | O10: withdrawn; replacement announced but not introduced | P10: The Senate register records the bill withdrawn in the House on 28 August. MoITT said it intended a fresh bill retaining the proposal’s essence. | R10: The pending bill ceased to advance; the replacement remained executive intent at cutoff. | S10: No operative telecom-law change arose from the withdrawn text, reducing immediate compliance impact but preserving policy uncertainty. | T10: Treat future legislation as a new event requiring a new text and parliamentary lifecycle. | U10: Watch for introduction, referral, amendments, passage, assent, Gazette and commencement. | V10: High | W10: Official executive and parliamentary records align on withdrawal. | X10: Successor text, title, introduction date and operative provisions. | Y10: include | Z10: IN_SPAN_DEVELOPMENT
A11: EVT-KP-20260821-DIGITAL-PAYMENTS | B11: KP Digital Payments Bill passage claim conflicts with official tracker | C11: DIGITAL_IDENTITY_DPI | D11: Khyber Pakhtunkhwa Assembly | E11: Khyber Pakhtunkhwa / Peshawar | F11: 2026-08-21 (reported) | G11: 46256 | H11: 2026-08-22T15:05Z (B004) | I11: 2026-08-22T15:05Z (B004) | J11: B004 | K11: S027 | L11: https://www.pakp.gov.pk/bill/the-khyber-pakhtunkhwa-promotion-of-digital-payments-bill-2026/ | M11: S028 | N11: https://tribune.com.pk/story/2625229/k-p-assembly-approves-digital-payments-bill | O11: officially referred to committee; reported passage unverified | P11: The official tracker currently shows the bill introduced on 6 April 2026 and referred to Standing Committee No. 10. | Q11: A news headline says the Assembly approved the bill on 21 August, while the article body also describes it as introduced. | R11: A reported passage claim appeared, but authoritative disposition did not confirm it. | S11: Misclassifying the bill as enacted would falsely create payment obligations and a rulemaking clock. | T11: No Act, assent, Gazette or commencement is verified. | U11: Recheck committee report, passed-bills register, assent and Gazette. | V11: High | W11: High on current official status; low on reported passage. | X11: Authoritative 21 August proceedings; final text; vote; assent; Gazette; commencement; rulemaking. | Y11: include as disputed status | Z11: CONTRADICTED_OR_UNRESOLVED
A12: EVT-KP-20260827-VIRTUAL-WORKPLACE | B12: KP committee recommends digital-workplace harassment amendments | C12: DATA_PROTECTION_GOVERNANCE | D12: KP Assembly Standing Committee | E12: Khyber Pakhtunkhwa / Peshawar | F12: 46261 | G12: 46261 | H12: 2026-08-27T14:06Z (B008) | I12: 2026-08-27T14:06Z (B008) | J12: B008 | K12: S029 | L12: https://dgipr.kp.gov.pk/sc-27-8-26/ | O12: committee recommendation; not enacted | P12: A provincial committee considered and recommended amendments extending workplace-protection concepts to digital, virtual and remote environments and electronic evidence. | R12: The proposal advanced at committee level only. | S12: It signals recognition of digitally mediated workplace harms but does not yet alter legal duties. | T12: Evidence, privacy, jurisdiction and platform-process rules remain central design questions. | U12: Track bill text, Assembly vote, assent, Gazette and rules. | V12: High | W12: Official provincial release is clear about committee stage. | X12: Amendment text; evidentiary safeguards; vote; assent; commencement. | Y12: include | Z12: IN_SPAN_DEVELOPMENT
A13: EVT-SECP-20260827-C19 | B13: SECP Circular No. 19 of 2026 on investor onboarding | C13: DATA_PROTECTION_GOVERNANCE | D13: Securities and Exchange Commission of Pakistan | E13: Federal / Islamabad | F13: issued 2026-08-25; posted 2026-08-27 | G13: 2026-08-27; press coverage 2026-08-28 | H13: 2026-08-27T14:06Z (B008) | I13: 2026-09-03T04:15Z (verification) | J13: B008 | K13: S101; S102 | L13: https://www.secp.gov.pk/document/circular-no-19-of-2026-consolidated-framework-for-investor-onboarding-secp-regulated-persons/ | https://www.secp.gov.pk/laws/circulars/ | M13: S103; S104 | N13: https://www.dawn.com/news/2025777 | https://www.brecorder.com/news/40436941 | O13: final issued circular; commencement date unstated; three-month transition | P13: Circular 19/2026 was issued on 25 August and posted on the official register on 27 August. It repeals Circular 6/2023 while preserving prior actions. For complete individual-customer documents, the maximum accept/decline period is one working day for Sehl/Sahulat accounts and two working days for Normal Accounts; deficiencies must be communicated within the same period and rejection reasons supplied in writing. Firms have three months to align forms and establish portal connectivity, subject to extension. | Q13: Government reporting linked the reform to a 2.5 million investor-base objective; that is policy context, not an intermediary obligation. | R13: A final onboarding framework replaced the 2023 circular and introduced measurable processing deadlines and transition requirements. | S13: The circular converts a general digitisation agenda into binding process obligations for specified securities and financial-market intermediaries. | T13: Do not infer an effective date, extend the individual-account turnaround to juridical applicants, or treat issuance as proof of intermediary compliance. | U13: Track clarification of the immediate-connectivity language, the transition end point, extensions, portal readiness, rejection data and supervisory compliance. | V13: High | W13: Official register and eight-page circular were inspected directly; dates and provisions were cross-checked against two reputable reports. | X13: Express effective date; juridical-person turnaround; reconciliation of immediate connectivity with the transition; extensions; operational compliance. | Y13: include | Z13: IN_SPAN_DEVELOPMENT
A14: EVT-PLAT-20260901-PUNJAB-U16 | B14: Punjab Assembly reportedly passes under-16 social-media resolution | C14: PLATFORM_TELECOM | D14: Punjab Assembly | E14: Punjab / Lahore | F14: 46266 | G14: 46266 | H14: 2026-09-01T16:51Z (B013) | I14: 2026-09-01T16:51Z (B013) | J14: B013 | M14: S032 | N14: https://humenglish.com/latest/punjab-assembly-passes-resolution-to-ban-social-media-accounts-for-under-16s/ | O14: reported non-binding resolution; official text unavailable | P14: A news report says the Assembly adopted a resolution urging restrictions and age verification for under-16 accounts. | R14: A provincial political recommendation entered the debate; no enacted platform duty followed. | S14: Age assurance could affect biometric processing, exclusion, appeals and federal-provincial competence. | T14: The resolution is agenda-setting, not legislation or a PTA rule. | U14: Obtain the official resolution and track any bill, PTA instrument or implementation design. | V14: Low | W14: One credible report; no official resolution text located. | X14: Official text; legal route; verification method; retention; redress; federal authority. | Y14: include with qualification | Z14: IN_SPAN_DEVELOPMENT
A15: EVT-PLAT-20260831-IHC-U16 | B15: IHC seeks replies in under-16 age-verification petition | C15: PLATFORM_TELECOM | D15: Islamabad High Court | E15: Islamabad / federal respondents | F15: 46265 | G15: 2026-08-31 and 2026-09-01 | H15: 2026-09-01T16:51Z (B013) | I15: 2026-09-03T02:21Z (B014) | J15: B013; B014 | M15: S033; S034 | N15: https://www.dawn.com/news/2026379 | https://www.brecorder.com/news/40437291/social-media-age-verification-ihc-direct-authorities-to-submit-reply | O15: procedural notice/reply stage; no final judgment | P15: Two news reports describe notices and a request for replies within 15 days in a petition concerning age verification. | R15: The petition moved into a response stage, not final adjudication. | S15: A future order could shape platform age assurance, regulator duties and privacy safeguards. | T15: No substantive rule or obligation should be inferred from notice issuance. | U15: Retrieve the authenticated order, respondent filings and later disposition. | V15: Medium | W15: Two reputable reports align; court order itself was not located. | X15: Authenticated order; petition text; respondents; filings; final disposition. | Y15: include | Z15: IN_SPAN_DEVELOPMENT
A16: EVT-ID-20260901-NADRA-FBISE | B16: NADRA–FBISE student identity and certificate integration agreement | C16: DIGITAL_IDENTITY_DPI | D16: NADRA; Federal Board of Intermediate and Secondary Education | E16: Islamabad / national | F16: 46266 | G16: 46266 | H16: 2026-09-01T16:51Z (B013) | I16: 2026-09-01T16:51Z (B013) | J16: B013 | K16: S035 | L16: https://www.app.com.pk/national/nadra-fbise-sign-agreement-to-integrate-student-registration-educational-certificates-system/ | O16: agreement signed; deployment not evidenced | P16: APP reports an agreement for mutual exchange of name, father’s name and date of birth, with a planned secure digital wallet for certificates. | R16: The agencies formalized an integration intention; no production milestone or data-protection instrument was published. | S16: The project involves student/child data, identity matching and credential recovery, making legal basis and safeguards consequential. | T16: A signed agreement is not proof that a secure wallet or live data exchange is operating. | U16: Seek agreement text, data-flow diagrams, access controls, retention, correction, breach response, audits and launch acceptance. | V16: Medium | W16: Official news-agency report; underlying instrument and system evidence unavailable. | X16: Agreement text; legal basis; production status; minimisation; access/logging; retention; child safeguards; redress. | Y16: include | Z16: IN_SPAN_DEVELOPMENT
A17: EVT-PROC-20260818-31-AI-HUBS | B17: National AI Hubs procurement advertised and closed | C17: PROCUREMENT_PROGRAM_DELIVERY | D17: MoITT — Digital Emerging Technologies Wing | E17: Islamabad / national | F17: 2026-08-18 to 2026-08-31 | G17: 46252 | H17: 2026-08-18T19:38Z (B001) | I17: 2026-09-03T02:21Z (B014) | J17: B001; B002; B003; B004; B005; B006; B007; B008; B009; B010; B011; B012; B013; B014 | K17: S036; S037 | L17: https://epms.ppra.gov.pk/public/tenders/tender-details/TS0000010287E | https://epads.gov.pk/opportunities/federal/procurements/71677 | O17: closed for bids; pre-evaluation/pre-award | P17: The consultancy tender was advertised 18 August and the current record shows closing at 14:00 PKT and opening at 14:30 on 31 August, single-stage two-envelope, PKR 3 million bid security and 180-day validity. No evaluation or award was visible. | Q17: The tender history retains an inconsistent 19 August closing entry. | R17: The procurement moved from open to closed, but not to evaluated, awarded, contracted or delivered. | S17: The tender is a potential delivery vehicle for the National AI Policy, but no hub, site, budget expenditure or service exists merely because bidding closed. | T17: Procurement momentum remains upstream of implementation. | U17: Track opening record, bidders, technical evaluation, grievance, award, contract, sites, equipment and acceptance. | V17: High | W17: Official procurement records; internal history conflict preserved. | X17: Bidder/opening record; evaluation; award; contract; locations; equipment; safeguards; acceptance. | Y17: include | Z17: IN_SPAN_DEVELOPMENT
A18: EVT-PROC-20260819-MOITT-TRAINING | B18: MoITT AI capacity-building procurement reaches final evaluation | C18: WORKFORCE_RESEARCH_EDUCATION | D18: MoITT | E18: Federal / online | F18: 46253 | G18: 46253 | H18: 2026-08-20T14:50Z (B002) | I18: 2026-08-20T14:50Z (B002) | J18: B002 | K18: S038; S039 | L18: https://epms.ppra.gov.pk/public/tenders/tender-details/TS0000006913E | https://epms.ppra.gov.pk/public/evaluations?page=7 | O18: final evaluation; not awarded | P18: The procurement targets 20,000 online trainings; the evaluation listed 17 bids and NCBMS as lowest. | R18: Bid comparison reached final-evaluation stage. | S18: Potential workforce scale is material, but bidder ranking is not delivered training. | T18: Outcome claims should wait for award, contract, enrolment, completion and assessment evidence. | U18: Track award, contract value, curriculum, enrolment, completions and independent learning outcomes. | V18: High | W18: Official procurement record; stage distinction is clear. | X18: Award; contract; value; provider obligations; delivery; completion and outcome evidence. | Y18: include | Z18: IN_SPAN_DEVELOPMENT
A19: EVT-PROC-20260821-28-NAVTTC-AI-SERVICES | B19: NAVTTC AI-enabled services procurement advances from technical to final evaluation | C19: PROCUREMENT_PROGRAM_DELIVERY | D19: NAVTTC | E19: Federal / Pakistan | F19: 2026-08-21 and 2026-08-28 | G19: 2026-08-21 and 2026-08-28 | H19: 2026-08-21T15:05Z (B003) | I19: 2026-08-28T14:52Z (B009) | J19: B003; B004; B008; B009 | K19: S040; S041; S042 | L19: https://epms.ppra.gov.pk/public/tenders/tender-details/TS0000010237E | https://epms.ppra.gov.pk/public/evaluations?page=1 | https://epms.ppra.gov.pk/public/evaluations?page=4 | O19: final evaluation; not awarded | P19: A technical evaluation on 21 August covered six bids; a final evaluation dated 28 August listed Mercurial Minds as lowest evaluated bidder. | R19: This was a genuine procurement-stage update, not duplicate coverage. | S19: It narrows the likely supplier but does not establish contract execution or an operational AI-enabled service. | T19: Procurement registers should be read as a lifecycle, not as binary project completion. | U19: Track award, contract, scope, data safeguards, deployment, tests and acceptance. | V19: High | W19: Official evaluation records at two stages. | X19: Award; price; signed contract; implementation scope; data governance; acceptance. | Y19: include | Z19: IN_SPAN_DEVELOPMENT
A20: EVT-PROC-20260827-PTA-DIRBS | B20: PTA AI-powered DIRBS tender closes | C20: AI_GOVERNANCE | D20: Pakistan Telecommunication Authority | E20: Federal / Pakistan | F20: 46261 | G20: 46244 | H20: 2026-08-18T19:38Z (B001) | I20: 2026-08-27T14:06Z (B008) | J20: B001; B002; B003; B004; B005; B006; B007; B008 | K20: S043; S044 | L20: https://epms.ppra.gov.pk/public/tenders/tender-details/TS0000011207E | https://epads.gov.pk/federal/annual-plan/procurement/2473/7564/2026-27 | O20: closed tender; no evaluation or award | P20: The consultancy tender advertised 10 August closed at 11:00 PKT on 27 August under a single-stage one-envelope procedure with 120-day validity. No result was visible. | Q20: Annual-plan and tender metadata do not fully align. | R20: Bidding closed; system design, vendor selection and deployment remain unverified. | S20: AI use in device-registration enforcement could affect lawful device access, false positives and procedural rights. | T20: Governance questions are material before procurement reaches operation. | U20: Demand legal basis, data inputs, testing, accuracy thresholds, human review, auditability, retention and appeals. | V20: High | W20: Official tender record for closure; technical and safeguards evidence absent. | X20: Metadata reconciliation; evaluation; award; architecture; accuracy; human review; retention; redress. | Y20: include | Z20: IN_SPAN_DEVELOPMENT
A21: EVT-PROC-20260820-NADRA-RACKS | B21: NADRA NDW racks, containment and PDU tender closes | C21: COMPUTE_CLOUD_DATACENTRE | D21: NADRA | E21: Federal / Pakistan | F21: 46254 | G21: 46232 | H21: 2026-08-20T14:50Z (B002) | I21: 2026-08-20T14:50Z (B002) | J21: B002 | K21: S045 | L21: https://epms.ppra.gov.pk/public/tenders/tender-details/TS0000010535E | O21: closed tender; pre-evaluation | P21: The tender for NDW racks, containment systems and rack PDUs closed 20 August at 11:00 PKT with PKR 580,000 bid security and 120-day validity. | R21: Bidding closed without a visible downstream result. | S21: The procurement is enabling physical infrastructure, not proof of expanded compute capacity or service resilience. | T21: Capacity should be counted only after delivery, testing and acceptance. | U21: Track evaluation, award, installation, commissioning and acceptance. | V21: High | W21: Official procurement record. | X21: Evaluation; award; value; delivery; commissioning; accepted capacity. | Y21: include | Z21: IN_SPAN_DEVELOPMENT
A22: EVT-PROC-20260820-NADRA-SWITCHES | B22: NADRA branch-switch and management-licence tender closes | C22: CONNECTIVITY_ENERGY_RESILIENCE | D22: NADRA | E22: Federal / Pakistan | F22: 46254 | G22: 2026 | H22: 2026-08-20T14:50Z (B002) | I22: 2026-08-20T14:50Z (B002) | J22: B002 | K22: S046 | L22: https://epms.ppra.gov.pk/public/tenders/tender-details/TS0000010591E | O22: closed tender; pre-evaluation | P22: The tender covered 237 Layer-2 switches, 30 PoE switches and 267 central-management licences; it closed 20 August at 11:00 PKT with PKR 600,000 bid security and 120-day validity. | R22: Bidding closed without a visible evaluation or award. | S22: It may improve branch-network manageability but is not AI compute or proven operational resilience. | T22: Keep networking inputs distinct from compute capacity. | U22: Track evaluation, award, rollout, security configuration and acceptance. | V22: High | W22: Official procurement record. | X22: Evaluation; award; delivery; deployment; security acceptance. | Y22: include | Z22: IN_SPAN_DEVELOPMENT
A23: EVT-PROC-20260828-WHO-BALOCHISTAN-GIS | B23: WHO GIS-enabled EPI microplanning and NEIR integration RFP updated | C23: PROCUREMENT_PROGRAM_DELIVERY | D23: World Health Organization Pakistan | E23: Balochistan | F23: 2026-08-27 pre-bid meeting; deadline extended to 2026-09-06 | G23: 2026-08-24 in B006 capture; current page displays 2026-08-28 | H23: 2026-08-24T19:25Z (B006, earlier schedule observed) | I23: 2026-09-03 verification | J23: B006 | K23: S047 | L23: https://www.ungm.org/Public/Notice/310156 | O23: open RFP; deadline extended; pre-award | P23: B006 captured the notice on 24 August and transcribed its publication field as 24 August; the current mutable UNGM page instead displays publication on 28 August. The current page also records a 27 August 14:00 PKT pre-bid meeting and an extended deadline of 6 September 2026 at 11:00 PKT for GIS-enabled EPI microplanning and NEIR integration. | Q23: The observed publication date conflicts: 24 August in B006 versus 28 August on the current page. The page also retains superseded 24 and 31 August deadlines in its update history. | R23: The mutable record and schedule were revised; no award or implementation occurred in the period. | S23: The procurement involves geospatial and immunisation data, requiring careful access, retention, hosting and public-health governance. | T23: It is a live procurement signal, not a deployed health-data system. | U23: Track award, architecture, security, hosting, role-based access, retention and ethics controls. | V23: High | W23: Current international procurement record opened directly; version history preserved. | X23: Award; contract; data controller/processor roles; hosting; access; retention; ethics; production acceptance. | Y23: include | Z23: IN_SPAN_DEVELOPMENT
A24: EVT-TEL-20260827-JAZZ-5G | B24: Jazz reports reaching 1,000 live 5G sites | C24: PLATFORM_TELECOM | D24: Jazz | E24: Ten Pakistani cities | F24: 46261 | G24: 46261 | H24: 2026-08-28T14:52Z (B009) | I24: 2026-08-28T14:52Z (B009) | J24: B009 | K24: S048; S049 | L24: https://jazz.com.pk/media-center/detail/jazz-becomes-first-operator-to-reach-1000-5g-sites | https://jazz.com.pk/media-center/detail/jazz-secures-190-mhz-spectrum-to-accelerate-pakistans-5g-future | O24: company-reported operational footprint | P24: Jazz publicly reported 1,000 live 5G sites across ten cities, a target of 2,500 by end-2026, 190 MHz of spectrum and a prior US$1 billion commitment. | Q24: Operational-site and investment figures are company claims. | R24: The operator announced a footprint milestone during the reporting period. | S24: 5G reach influences edge connectivity and enterprise/cloud adoption, but site count does not establish coverage quality, affordability or realized capex. | T24: Treat the milestone as direct-company evidence pending independent coverage/QoS validation. | U24: Verify coverage maps, independent QoS, spectrum deployment and realized investment. | V24: Medium | W24: Direct company release; independent validation absent. | X24: Site definitions; geographic coverage; QoS; user access; realized capex. | Y24: include | Z24: IN_SPAN_DEVELOPMENT
A25: EVT-TEL-20260821-25-FAB-MONITORING | B25: FAB signs spectrum-monitoring equipment contract | C25: CONNECTIVITY_ENERGY_RESILIENCE | D25: Frequency Allocation Board; Rohde & Schwarz | E25: Islamabad / national | F25: 46255 | G25: 46259 | H25: 2026-08-29T14:38Z (B010) | I25: 2026-08-29T14:38Z (B010) | J25: B010 | K25: S050 | L25: https://epms.ppra.gov.pk/public/contracts/contract-details/PCN-3884318406 | O25: signed contract; commissioning unverified | P25: The contract record lists Rohde & Schwarz, PKR 196,308,167, two bids, three digital RF receivers, four sensor systems, training, one-year warranty and ten-year support; signed 21 August and published 25 August. | R25: The procurement reached signed-contract stage. | S25: It can strengthen spectrum oversight relevant to 5G reliability, but equipment is not operational until installed and accepted. | T25: This is stronger than an evaluation but weaker than commissioned capability. | U25: Track delivery, installation, training, commissioning, acceptance and utilisation. | V25: High | W25: Official contract record with vendor, value and scope. | X25: Delivery; installation sites; commissioning; acceptance; operational use. | Y25: include | Z25: IN_SPAN_DEVELOPMENT
A26: EVT-INF-20260821-SKY47-COMMERCE | B26: Commerce Ministry explores sovereign cloud and AI trade infrastructure with PDA and Sky47 | C26: COMPUTE_CLOUD_DATACENTRE | D26: Ministry of Commerce; PDA; Sky47 | E26: Federal / Pakistan | F26: 46255 | G26: 46255 | H26: 2026-09-01T16:51Z (B013, retrospective extraction) | I26: 2026-09-01T16:51Z (B013) | J26: B013 | K26: S051 | L26: https://pid.gov.pk/site/press_detail/33671 | O26: exploratory meeting / technical consultation | P26: The minister held separate meetings with PDA and Sky47 on data exchange, sovereign cloud, cybersecurity, disaster recovery, AI-enabled trade analysis and procurement reform; teams were directed to continue technical consultations and develop proposals. | Q26: Sky47 briefed the minister on existing infrastructure and expansion plans. | R26: A government-use discussion occurred; no contract, migration or activation was reported. | S26: The discussion identifies possible public-sector demand and governance questions around authorized data, procurement and domestic hosting. | T26: The 8.5 MW Karakoram-01 capacity belongs to a July baseline, not this meeting. | U26: Track approved architecture, procurement, data classification, cloud contracts, migration and acceptance. | V26: High | W26: Official release directly supports the meeting and forward-looking status. | X26: Proposal; contract; workloads; hosting; data-sharing controls; budget; acceptance. | Y26: include | Z26: IN_SPAN_DEVELOPMENT
A27: EVT-PART-20260827-RESECURITY-SKY47 | B27: Resecurity–Sky47 cybersecurity cooperation MoU announced | C27: FUNDING_INVESTMENT_PARTNERSHIP | D27: Resecurity; Sky47 | E27: Pakistan | F27: signing date and place unstated; first-party announcement 2026-08-27 | G27: 2026-08-27; advertorial 2026-08-29, modified 2026-08-31 | H27: 2026-08-29T14:38Z (B010) | I27: 2026-09-03T04:15Z (verification) | J27: B010 | K27: S086 | L27: https://www.linkedin.com/posts/sky47limited_sky47-resecurity-cybersecurity-activity-7498665122295517184-fA11 | M27: S087; S055 | N27: https://c-suite.exchange/sky47-and-resecurity-sign-mou-to-strengthen-cybersecurity-collaboration/ | https://www.dawn.com/news/2025965/resecurity-and-sky47-partner-to-enable-sovereign-cybersecurity-and-ai-infrastructure-in-pakistan | O27: signed exploratory MoU; no deployment or service contract | P27: Sky47 announced the signing of an MoU with Resecurity and said the parties will explore cooperation. The first-party announcement was posted on 27 August at approximately 13:58 PKT; neither it nor later reports states the physical signing date or place. | Q27: A Resecurity-supplied Dawn advertorial says the parties intend to explore secure deployment models for threat intelligence, fraud prevention, digital-risk monitoring, identity protection, AI-powered cybersecurity workloads and GPU-enabled infrastructure. | R27: A prospective cooperation framework was signed and announced; no customer, value, duration, workload, capacity or delivery date was disclosed. | S27: It indicates private demand for data residency and in-country hosting but does not quantify realized capacity. | T27: Treat the MoU as a verified relationship milestone, not as service delivery or proof of new AI/GPU capacity. | U27: Verify contracts, customers, data-processing terms, certifications, GPU inventory, deployment and exit obligations. | V27: High | W27: First-party announcement verifies the MoU and prospective language; delivery remains low-confidence and the signing date is unknown. | X27: Physical signing date/place; term; value; contract; customers; workloads; facility; GPUs; processing terms; certifications; deployment. | Y27: include | Z27: IN_SPAN_DEVELOPMENT
A28: EVT-RD-20260829-PSEB-NED | B28: PSEB–NED semiconductor education and research cluster contract signed | C28: WORKFORCE_RESEARCH_EDUCATION | D28: Pakistan Software Export Board; NED University | E28: Karachi / South Region | F28: 46263 | G28: 46263 | H28: 2026-08-29T14:38Z (B010) | I28: 2026-08-29T14:38Z (B010) | J28: B010 | K28: S088; S089; S090 | L28: https://pid.gov.pk/site/press_detail/33749 | https://techdestination.com/wp-content/uploads/2025/09/Request-for-Proposal-NSHRDP-SERC-Procurement-2.51.pdf | https://pid.gov.pk/site/press_detail/32338 | M28: S056; S057 | N28: https://www.moitt.gov.pk/NewsDetail/MTJmOTg2OGQtOTNlYi00MDZjLTk0MDktNGRiMmQzMTEzYTdm | https://www.neduet.edu.pk/content/events | O28: contract signed / lead-university designation; commencement and disbursement unverified | P28: PID reports a contract naming NED the South Region lead university and completing three regional SERC agreements. It reports 270 students across all regions and a target exceeding 7,200 professionals by 2030. The procurement framework requires inspection and a commencement certificate before academic activity and disbursement. | Q28: The ministry says INSPIRE moves into full-scale implementation. The PKR 4.844 billion figure cited elsewhere is the entire National Semiconductor Human Resource Development Program budget, not this NED contract. | R28: The South Region institutional agreement was reported complete. | S28: This creates an institutional workforce/research structure, though training targets are not yet completed outcomes. | T28: The contract milestone is stronger than an MoU, but it does not establish commencement, disbursement, laboratories, training or completed outputs; the NED contract value is undisclosed. | U28: Track contract publication, funding, labs, equipment, enrolment, completion and placements/research outputs. | V28: High | W28: Official PID release and procurement framework support contract status and downstream conditions; contract text and delivery evidence are absent. | X28: Contract text/value; commencement certificate; disbursement; lab specifications; delivery calendar; enrolment by cluster; outputs. | Y28: include | Z28: IN_SPAN_DEVELOPMENT
A29: EVT-PUNJAB-20260828-DATALAKE | B29: Punjab announces Data Lake and OneMap integration claims | C29: DIGITAL_IDENTITY_DPI | D29: Government of Punjab | E29: Punjab / Lahore; announcement at Guiyang event | F29: 46262 | G29: 46262 | H29: 2026-08-28T14:52Z (B009) | I29: 2026-09-01T16:51Z (B013) | J29: B009; B010; B013 | K29: S058 | L29: https://www.app.com.pk/punjab/maryam-delivers-thought-provoking-address-at-big-data-industry-expo/ | O29: officially claimed launch/integration; technical operation unverified | P29: APP relays Punjab claims of more than 12 TB of geospatial data, 31 departments and over 6,000 datasets in a Data Lake/OneMap context, alongside sovereign-cloud and AI-office ambitions. | R29: The province publicly framed a cross-department data platform as a delivery milestone. | S29: Centralised geospatial/government data can improve planning while magnifying legal-basis, access, security, correction and reuse risks. | T29: Treat quantities as government claims; no technical acceptance, architecture or legal instrument was located. | U29: Verify datasets, controllers, hosting, access, audit, retention, public transparency and acceptance tests. | V29: Medium | W29: Official news-agency report; underlying technical and legal evidence unavailable. | X29: Legal basis; architecture; dataset inventory; hosting; access; retention; audit; procurement; acceptance. | Y29: include | Z29: IN_SPAN_DEVELOPMENT
A30: EVT-KP-20260828-DIGITAL-DELIVERY | B30: KP government reports digital-service and cyber delivery | C30: DIGITAL_IDENTITY_DPI | D30: Government of Khyber Pakhtunkhwa | E30: Khyber Pakhtunkhwa | F30: 46261 | G30: 46262 | H30: 2026-08-28T14:52Z (B009) | I30: 2026-08-28T14:52Z (B009) | J30: B009 | K30: S059 | L30: https://dgipr.kp.gov.pk/stit-28-8-26/ | M30: S091 | N30: https://tribune.com.pk/story/2626183/citizen-facilitation-centres-planned?amp=1 | O30: district-centre directive plus provincial self-report; outcomes not independently verified | P30: At a 27 August performance briefing, the minister directed establishment of citizen facilitation centres in every district. The department also self-reported six model IT labs in merged-district schools, six digitised departments, an established Cyber Response Emergency Centre and a Peshawar citizen centre ready for inauguration. | R30: A new province-wide facilitation-centre directive was issued while earlier delivery items were restated as institutional claims. | S30: The portfolio suggests subnational service capacity but cannot be compared without budgets, service volumes and outcome measures. | T30: Institutional self-report is evidence of a claim, not independent proof of effectiveness. | U30: Obtain project lists, budgets, named sites, usage, uptime, incident and outcome metrics. | V30: Medium | W30: Official provincial statement supports the meeting and directive; operational assertions are not independently audited. | X30: District rollout plan; budgets; centre list; opening dates; service volumes; uptime; cybersecurity outcomes; independent validation. | Y30: include | Z30: IN_SPAN_DEVELOPMENT
A31: EVT-PUNJAB-20260828-HUAWEI | B31: Punjab and Huawei announce AI-training commitments and discuss data centres | C31: FUNDING_INVESTMENT_PARTNERSHIP | D31: Government of Punjab; Huawei | E31: Punjab / Nawaz Sharif IT City | F31: 46262 | G31: 2026-08-28; secondary report 2026-08-29 | H31: 2026-08-29T14:38Z (B010) | I31: 2026-08-29T14:38Z (B010) | J31: B010 | K31: S092 | L31: https://www.app.com.pk/punjab/punjab-cm-huawei-agree-to-expand-ai-digital-cooperation/ | M31: S060 | N31: https://www.brecorder.com/news/40436971/punjab-huawei-agree-to-expand-ai-digital-cooperation | O31: government–vendor meeting and announced commitments; no signed instrument or award | P31: APP reports a 28 August meeting and commitments to train 1,000 Punjab youth as Huawei master trainers and 300 women trainers in AI. Six data centres, including a sovereign centre at Nawaz Sharif IT City, were discussed; an AI Delivery Unit was proposed; Punjab stated a 2029 target for an AI-integrated system. | Q31: The sources do not clarify whether the 300 women are included within or additional to the 1,000 youth. Separate language describing a four-tier system is not evidence of a Tier IV data-centre classification. | R31: Training commitments and infrastructure proposals were announced at a meeting, without a published MoU, contract, financing or delivery schedule. | S31: Vendor concentration, procurement, data residency, power and exit terms would be material if the proposal advances. | T31: Do not count six operational data centres or committed capacity from this report. | U31: Seek the agreement, financing, sites, capacity, procurement route, power plan, safeguards and acceptance milestones. | V31: Medium | W31: Government-side APP account verifies the announcement; Huawei confirmation and operative instruments are absent, and delivery confidence is low. | X31: Signed text; financing; sites; capacity; procurement; power; data controls; delivery. | Y31: include with qualification | Z31: IN_SPAN_DEVELOPMENT
A32: EVT-PUNJAB-20260830-ALIBABA | B32: Punjab and Alibaba Cloud discuss AI public-service partnership | C32: FUNDING_INVESTMENT_PARTNERSHIP | D32: Government of Punjab; Alibaba Cloud | E32: Punjab / meeting in China | F32: 46264 | G32: 46264 | H32: 2026-08-30T14:57Z (B011) | I32: 2026-08-31T14:55Z (B012) | J32: B011; B012 | K32: S061; S062 | L32: https://www.app.com.pk/punjab/alibaba-cloud-shows-keen-interest-in-punjabs-it-sector-cm-maryam-invites-chinese-ai-collaboration/ | https://radio.gov.pk/30-08-2026/ai-being-integrated-into-governance-system-in-punjab-cm | M32: S093; S094 | N32: https://tribune.com.pk/story/2626664/chinese-firm-shows-interest-in-punjab-it-sector?amp=1 | https://radio.gov.pk/24-05-2026/pakistan-alibaba-group-ink-agreements-to-boost-digital-economy-cooperation | O32: exploratory discussion / potential partnership | P32: Official media report a 30 August exploratory meeting on a potential strategic partnership using AI in agriculture, healthcare, socio-economic programmes and climate forecasting; an Alibaba executive said data-centre discussions were under way. | Q32: The executive's reference to an MoU signed before the prime minister appears to concern earlier national agreements, not a new Punjab agreement on 30 August. | R32: A vendor-government discussion occurred; no signed text, workload or implementation followed in the period. | S32: Potential public-service AI creates procurement, hosting, transfer, accountability and vendor-exit questions. | T32: The available evidence supports exploration, not an operational deployment. | U32: Track agreement, site, financing, datasets, model governance, procurement, hosting and acceptance. | V32: Medium | W32: Two official-state reports align on a discussion; implementation evidence absent. | X32: Any new signed text; relationship to May national agreements; scope; financing; capacity; data flows; models; hosting; procurement; launch. | Y32: include | Z32: IN_SPAN_DEVELOPMENT
A33: EVT-KP-20260828-WORLDBANK-DIGITAL-ENERGY | B33: KP–World Bank talks link digital infrastructure, AI and energy | C33: FUNDING_INVESTMENT_PARTNERSHIP | D33: Government of Khyber Pakhtunkhwa; World Bank | E33: Khyber Pakhtunkhwa / Peshawar | F33: 2026-08-28 (page says Friday) | G33: 46265 | H33: 2026-08-31T14:55Z (B012) | I33: 2026-09-03T02:21Z (B014) | J33: B012; B014 | K33: S063 | L33: https://dgipr.kp.gov.pk/world-bank-delegation-meets-khyber-pakhtunkhwa-government-to-discuss-it-digital-infrastructure-and-energy-initiatives/ | M33: S095 | N33: https://www.brecorder.com/news/40437177/advisor-cs-kp-world-bank-team-discuss-it-digital-infrastructure-list-6 | O33: exploratory meeting; joint working group agreed; no financing | P33: The provincial release was published 31 August and says the meeting occurred Friday, which resolves to 28 August. It reports agreement to create a joint working group to examine technical and other modalities around digital transformation, AI, a KP data centre, hydropower and transmission. | R33: The parties agreed an exploratory working-group mechanism; no World Bank finance, project approval, assessment, site or technical parameters were disclosed. | S33: The linkage recognizes that compute infrastructure depends on reliable power and transmission. | T33: It is planning-stage evidence, not World Bank financing or a data-centre commitment. | U33: Track formal assessment, working group, finance, site, load, grid and safeguards. | V33: Medium | W33: Official provincial release and calendar inference support the meeting and working group; no World Bank source independently confirms it. | X33: World Bank confirmation; working-group terms; assessment; financing; site; capacity; energy plan. | Y33: include | Z33: IN_SPAN_DEVELOPMENT
A34: EVT-INTL-20260901-SAUDI-CLOUD-MEETING | B34: Pakistan and Saudi Arabia announce deeper cloud and cybersecurity cooperation | C34: FUNDING_INVESTMENT_PARTNERSHIP | D34: MoITT; Saudi Ministry of Communications and Information Technology | E34: Riyadh / Pakistan–Saudi | F34: 46266 | G34: 46266 | H34: 2026-09-01T16:51Z (B013) | I34: 2026-09-01T16:51Z (B013) | J34: B013 | K34: S064 | L34: https://www.app.com.pk/national/shaza-meets-saudi-minister-of-communications-and-information-technology/ | O34: ministerial cooperation announcement; no cloud project instrument | P34: APP reports that ministers agreed to enhance cooperation in cloud infrastructure and cybersecurity and discussed B2B partnerships, technology exports, investment, skills and technology transfer. | R34: A ministerial cooperation statement entered the record. | S34: It could open investment and export channels, but no cloud workload, capital commitment, safeguards or timetable exists in the evidence. | T34: This cloud-cooperation announcement is separate from the Saudi NCA–MoITT cybersecurity MoU and should not be converted into a funded infrastructure project. | U34: Track instrument, counterparties, workplan, financing, hosting, transfers, security and exit terms. | V34: Medium | W34: Official news-agency report; no bilateral text or project documentation. | X34: Instrument; projects; finance; parties; workplan; hosting; data transfers; cybersecurity obligations. | Y34: include | Z34: IN_SPAN_DEVELOPMENT
A35: EVT-INTL-20260901-SAUDI-NCA-CYBER-MOU | B35: Saudi NCA and Pakistan MoITT sign cybersecurity MoU | C35: CYBERSECURITY | D35: Saudi National Cybersecurity Authority; Pakistan Ministry of IT and Telecommunication | E35: Riyadh / Pakistan–Saudi | F35: 46266 | G35: 2026-09-01; Pakistani corroboration 2026-09-02 | H35: 2026-09-03T04:15Z (verification; not captured in B001–B014) | I35: 2026-09-03T04:15Z (verification) | K35: S096 | L35: https://nca.gov.sa/ar/news/2581/ | M35: S097; S098 | N35: https://www.radio.gov.pk/02-09-2026/pakistan-saudi-arabia-sign-mou-in-area-of-cybersecurity | https://www.app.com.pk/national/pakistan-saudi-arabia-sign-cybersecurity-agreement/ | O35: signed bilateral cybersecurity MoU; implementation not evidenced | P35: The Saudi National Cybersecurity Authority and Pakistan's MoITT signed a cybersecurity MoU on 1 September in Riyadh. The Saudi authority's page is dated 1 September and was last modified at 16:23 AST; Pakistani official outlets corroborated the signing on 2 September. | Q35: Official accounts describe cooperation in cybersecurity without publishing the full instrument. | R35: A formal bilateral cybersecurity instrument was signed; the supplied briefing set missed it despite covering adjacent Saudi meetings. | S35: The event is substantively stronger than a ministerial discussion and exposes the monitoring corpus's severe cadence and discovery gaps. | T35: Signed-instrument status is verified, but no operational programme, budget or transfer mechanism should be inferred. | U35: Obtain the MoU, term, workplan, participating agencies, funding, information-sharing rules, data safeguards and delivery evidence. | V35: High | W35: A first-party Saudi authority release and two Pakistani official sources independently confirm signing; implementation particulars are absent. | X35: Full text; term; workplan; financing; data-sharing; operational mechanism; outputs. | Y35: include; verification-discovered event absent from briefing corpus | Z35: IN_SPAN_DEVELOPMENT
A36: EVT-INTL-20260901-SAUDI-SDAIA-AI-DATA | B36: Pakistan and Saudi data authority discuss AI and data-governance cooperation | C36: DATA_PROTECTION_GOVERNANCE | D36: Pakistan MoITT; Saudi Data and Artificial Intelligence Authority | E36: Riyadh / Pakistan–Saudi | F36: 46266 | G36: 46266 | H36: 2026-09-03T04:15Z (verification; not captured in B001–B014) | I36: 2026-09-03T04:15Z (verification) | K36: S109 | L36: https://www.app.com.pk/national/pakistan-saudi-arabia-agree-to-strengthen-cooperation-in-ai-data-governance/ | O36: exploratory official meeting; no instrument or project | P36: APP reports a 1 September meeting between Pakistan's IT minister and the Saudi Data and Artificial Intelligence Authority on possible cooperation in AI and data governance. | R36: A separate AI/data-governance dialogue appeared during verification but was absent from the briefing corpus. | S36: It signals international policy coordination, while the absence of an instrument leaves obligations and implementation undefined. | T36: Treat as agenda-setting, not a signed agreement, funded programme or shared-data arrangement. | U36: Track any signed instrument, workplan, standards alignment, cross-border data terms, projects, financing and safeguards. | V36: Medium | W36: An official news-agency report verifies the meeting; no Saudi first-party confirmation or instrument was located. | X36: Counterparty confirmation; instrument; workplan; projects; financing; data transfers; safeguards. | Y36: include with qualification; verification-discovered event absent from briefing corpus | Z36: IN_SPAN_DEVELOPMENT
A37: EVT-DPI-20260901-OPEN-STACK | B37: Pakistan says national digital stack is under development and may be shared when complete | C37: DIGITAL_IDENTITY_DPI | D37: MoITT; Pakistan Digital Authority | E37: Riyadh announcement / international recipients | F37: 46266 | G37: 46266 | H37: 2026-09-01T16:51Z (B013) | I37: 2026-09-01T16:51Z (B013) | J37: B013 | K37: S099 | L37: https://moitt.gov.pk/NewsDetail/NWI0ZjIwOTctYzc1Ny00NzBkLTliNGQtMzc2NWQxOTQyMzlk | M37: S065 | N37: https://www.arabnews.pk/pakistan/minister-tells-saudi-expo-pakistan-will-share-digital-infrastructure-free-with-emerging-economies-3000008 | O37: under development; future sharing intention; not released or deployed | P37: MoITT says Pakistan is developing a national digital stack spanning identity, data and payments and intends to share it free with frontier and emerging economies when complete. The event pavilion included 25 startups and 50 Pakistani technology firms; those are event-context figures, not stack capacity. | R37: An outward-facing future-sharing intention was announced while the official source expressly described the stack as unfinished. | S37: Exportable DPI could create interoperability and influence, but also transfers domestic governance assumptions across jurisdictions. | T37: No released code, licence, completed system or international deployment exists in the evidence; free-to-share is not yet a verified open-source release. | U37: Verify repositories, licence, architecture, security audit, recipients, budget and pilots. | V37: High | W37: Official ministry source directly states the under-development status; completion and future sharing remain unverified. | X37: Code; licence; readiness; architecture; recipients; security; privacy; audited pilots. | Y37: include with qualification | Z37: IN_SPAN_DEVELOPMENT
